Workbook

Sheet Data
A1: update_date | B1: resquest_system | C1: service_oper | D1: count
A2: 46223 | D2: 1
A3: 46223 | B3: AML | C3: FuzzySearchAllListInfoPlusMA | D3: 64
A4: 46223 | B4: AML | C4: GetAllCodeTablePlusMA | D4: 15
A5: 46223 | B5: AML | C5: GetListSubTypePlusMA | D5: 12
A6: 46223 | B6: AML | C6: SearchAllListInfoPlusMA | D6: 511
A7: 46223 | B7: AML | C7: UploadNetbay | D7: 1
A8: 46223 | B8: AMSC_POPAC | C8: RegulatoryVerificationPlusMA | D8: 7
A9: 46223 | B9: BASE24WS_CHKAML | C9: SearchAMLListInfoByCid | D9: 130238
A10: 46223 | B10: BASE24WS_CHKAML | C10: AuthService | D10: 4
A11: 46223 | B11: BCL | C11: SearchAllListInfo | D11: 35
A12: 46223 | B12: BCM | C12: SearchAllListInfo | D12: 96
A13: 46223 | B13: BIZNEXT_EM | C13: RegulatoryVerificationPlusMA | D13: 323
A14: 46223 | B14: BZ | C14: AddPartyFATCAInfo | D14: 56
... A146: 46223 | B146: XB_Cross-Border | C146: RegulatoryVerificationPlusMA | D146: 4
A147: 46224 | D147: 1
A148: 46224 | B148: AML | C148: FuzzySearchAllListInfoPlusMA | D148: 7
A149: 46224 | B149: AML | C149: GetAllCodeTablePlusMA | D149: 3
A150: 46224 | B150: AML | C150: GetListSubTypePlusMA | D150: 1
A151: 46224 | B151: AML | C151: SearchAllListInfoPlusMA | D151: 460
A152: 46224 | B152: AMSC_POPAC | C152: RegulatoryVerificationPlusMA | D152: 5
A153: 46224 | B153: BASE24WS_CHKAML | C153: SearchAMLListInfoByCid | D153: 118085
A154: 46224 | B154: BASE24WS_CHKAML | C154: AuthService | D154: 4
A155: 46224 | B155: BCL | C155: SearchAllListInfo | D155: 21
A156: 46224 | B156: BCM | C156: SearchAllListInfo | D156: 107
A157: 46224 | B157: BIZNEXT_EM | C157: RegulatoryVerificationPlusMA | D157: 353
A158: 46224 | B158: BZ | C158: kycScoreEngineForOrg | D158: 146
A159: 46224 | B159: BZ | C159: MaintainParentCompanyInfo | D159: 132
... A283: 46224 | B283: XB_Cross-Border | C283: RegulatoryVerificationPlusMA | D283: 1
A284: 46225 | D284: 1
A285: 46225 | B285: AML | C285: FuzzySearchAllListInfoPlusMA | D285: 10
A286: 46225 | B286: AML | C286: GetAllCodeTablePlusMA | D286: 11
A287: 46225 | B287: AML | C287: GetListSubTypePlusMA | D287: 8
A288: 46225 | B288: AML | C288: SearchAllListInfoPlusMA | D288: 455
A289: 46225 | B289: AMSC | C289: kycScoreEngineForOrg | D289: 2
A290: 46225 | B290: AMSC_POPAC | C290: RegulatoryVerificationPlusMA | D290: 11
A291: 46225 | B291: AMSC_POPAC | C291: AuthService | D291: 3
A292: 46225 | B292: AMSC_POPAC | C292: GetCRSOrgInfo | D292: 1
A293: 46225 | B293: AMSC_POPAC | C293: MaintainCRSOrgInfo | D293: 1
A294: 46225 | B294: BASE24WS_CHKAML | C294: SearchAMLListInfoByCid | D294: 112992
...

Sheet Service Growth
A1: Service | B1: 20-Jul | C1: 21-Jul | D1: 22-Jul | E1: 23-Jul | F1: 24-Jul | G1: 25-Jul | H1: 26-Jul | I1: Total | J1: Growth %
A2: UploadNetbay | B2: =SUMPRODUCT((Data!$A$2:$A$909=DATE(2026,7,20))*EXACT(Data!$C$2:$C$909,$A2)*Data!$D$2:$D$909) -> 11 | C2: =SUMPRODUCT((Data!$A$2:$A$909=DATE(2026,7,21))*EXACT(Data!$C$2:$C$909,$A2)*Data!$D$2:$D$909) -> 3 | D2: =SUMPRODUCT((Data!$A$2:$A$909=DATE(2026,7,22))*EXACT(Data!$C$2:$C$909,$A2)*Data!$D$2:$D$909) -> 9 | E2: =SUMPRODUCT((Data!$A$2:$A$909=DATE(2026,7,23))*EXACT(Data!$C$2:$C$909,$A2)*Data!$D$2:$D$909) -> 7 | F2: =SUMPRODUCT((Data!$A$2:$A$909=DATE(2026,7,24))*EXACT(Data!$C$2:$C$909,$A2)*Data!$D$2:$D$909) -> 7 | G2: =SUMPRODUCT((Data!$A$2:$A$909=DATE(2026,7,25))*EXACT(Data!$C$2:$C$909,$A2)*Data!$D$2:$D$909) -> 9 | H2: =SUMPRODUCT((Data!$A$2:$A$909=DATE(2026,7,26))*EXACT(Data!$C$2:$C$909,$A2)*Data!$D$2:$D$909) -> 9 | I2: =SUM(B2:H2) -> 55 | J2: =IF(B2=0,"",(H2-B2)/B2) -> -0.18181818
A3: SearchAMLListInfoByCid | B3: =SUMPRODUCT((Data!$A$2:$A$909=DATE(2026,7,20))*EXACT(Data!$C$2:$C$909,$A3)*Data!$D$2:$D$909) -> 130238 | C3: =SUMPRODUCT((Data!$A$2:$A$909=DATE(2026,7,21))*EXACT(Data!$C$2:$C$909,$A3)*Data!$D$2:$D$909) -> 118085 | D3: =SUMPRODUCT((Data!$A$2:$A$909=DATE(2026,7,22))*EXACT(Data!$C$2:$C$909,$A3)*Data!$D$2:$D$909) -> 112992 | E3: =SUMPRODUCT((Data!$A$2:$A$909=DATE(2026,7,23))*EXACT(Data!$C$2:$C$909,$A3)*Data!$D$2:$D$909) -> 108922 | F3: =SUMPRODUCT((Data!$A$2:$A$909=DATE(2026,7,24))*EXACT(Data!$C$2:$C$909,$A3)*Data!$D$2:$D$909) -> 115880 | G3: =SUMPRODUCT((Data!$A$2:$A$909=DATE(2026,7,25))*EXACT(Data!$C$2:$C$909,$A3)*Data!$D$2:$D$909) -> 111368 | H3: =SUMPRODUCT((Data!$A$2:$A$909=DATE(2026,7,26))*EXACT(Data!$C$2:$C$909,$A3)*Data!$D$2:$D$909) -> 103866 | I3: =SUM(B3:H3) -> 801351 | J3: =IF(B3=0,"",(H3-B3)/B3) -> -0.20249082
A4: UpdatePartyFATCAInfo | B4: =SUMPRODUCT((Data!$A$2:$A$909=DATE(2026,7,20))*EXACT(Data!$C$2:$C$909,$A4)*Data!$D$2:$D$909) -> 3200 | C4: =SUMPRODUCT((Data!$A$2:$A$909=DATE(2026,7,21))*EXACT(Data!$C$2:$C$909,$A4)*Data!$D$2:$D$909) -> 3045 | D4: =SUMPRODUCT((Data!$A$2:$A$909=DATE(2026,7,22))*EXACT(Data!$C$2:$C$909,$A4)*Data!$D$2:$D$909) -> 3236 | E4: =SUMPRODUCT((Data!$A$2:$A$909=DATE(2026,7,23))*EXACT(Data!$C$2:$C$909,$A4)*Data!$D$2:$D$909) -> 3468 | F4: =SUMPRODUCT((Data!$A$2:$A$909=DATE(2026,7,24))*EXACT(Data!$C$2:$C$909,$A4)*Data!$D$2:$D$909) -> 3017 | G4: =SUMPRODUCT((Data!$A$2:$A$909=DATE(2026,7,25))*EXACT(Data!$C$2:$C$909,$A4)*Data!$D$2:$D$909) -> 2464 | H4: =SUMPRODUCT((Data!$A$2:$A$909=DATE(2026,7,26))*EXACT(Data!$C$2:$C$909,$A4)*Data!$D$2:$D$909) -> 2367 | I4: =SUM(B4:H4) -> 20797 | J4: =IF(B4=0,"",(H4-B4)/B4) -> -0.2603125
A5: RegulatoryVerification | B5: =SUMPRODUCT((Data!$A$2:$A$909=DATE(2026,7,20))*EXACT(Data!$C$2:$C$909,$A5)*Data!$D$2:$D$909) -> 36622 | C5: =SUMPRODUCT((Data!$A$2:$A$909=DATE(2026,7,21))*EXACT(Data!$C$2:$C$909,$A5)*Data!$D$2:$D$909) -> 39756 | D5: =SUMPRODUCT((Data!$A$2:$A$909=DATE(2026,7,22))*EXACT(Data!$C$2:$C$909,$A5)*Data!$D$2:$D$909) -> 32755 | E5: =SUMPRODUCT((Data!$A$2:$A$909=DATE(2026,7,23))*EXACT(Data!$C$2:$C$909,$A5)*Data!$D$2:$D$909) -> 32435 | F5: =SUMPRODUCT((Data!$A$2:$A$909=DATE(2026,7,24))*EXACT(Data!$C$2:$C$909,$A5)*Data!$D$2:$D$909) -> 34956 | G5: =SUMPRODUCT((Data!$A$2:$A$909=DATE(2026,7,25))*EXACT(Data!$C$2:$C$909,$A5)*Data!$D$2:$D$909) -> 28996 | H5: =SUMPRODUCT((Data!$A$2:$A$909=DATE(2026,7,26))*EXACT(Data!$C$2:$C$909,$A5)*Data!$D$2:$D$909) -> 25400 | I5: =SUM(B5:H5) -> 230920 | J5: =IF(B5=0,"",(H5-B5)/B5) -> -0.30642783
A6: MaintainCRSPersonInfo | B6: =SUMPRODUCT((Data!$A$2:$A$909=DATE(2026,7,20))*EXACT(Data!$C$2:$C$909,$A6)*Data!$D$2:$D$909) -> 17933 | C6: =SUMPRODUCT((Data!$A$2:$A$909=DATE(2026,7,21))*EXACT(Data!$C$2:$C$909,$A6)*Data!$D$2:$D$909) -> 17898 | D6: =SUMPRODUCT((Data!$A$2:$A$909=DATE(2026,7,22))*EXACT(Data!$C$2:$C$909,$A6)*Data!$D$2:$D$909) -> 16624 | E6: =SUMPRODUCT((Data!$A$2:$A$909=DATE(2026,7,23))*EXACT(Data!$C$2:$C$909,$A6)*Data!$D$2:$D$909) -> 15643 | F6: =SUMPRODUCT((Data!$A$2:$A$909=DATE(2026,7,24))*EXACT(Data!$C$2:$C$909,$A6)*Data!$D$2:$D$909) -> 15256 | G6: =SUMPRODUCT((Data!$A$2:$A$909=DATE(2026,7,25))*EXACT(Data!$C$2:$C$909,$A6)*Data!$D$2:$D$909) -> 10612 | H6: =SUMPRODUCT((Data!$A$2:$A$909=DATE(2026,7,26))*EXACT(Data!$C$2:$C$909,$A6)*Data!$D$2:$D$909) -> 9397 | I6: =SUM(B6:H6) -> 103363 | J6: =IF(B6=0,"",(H6-B6)/B6) -> -0.47599398
A7: AddPartyFATCAInfo | B7: =SUMPRODUCT((Data!$A$2:$A$909=DATE(2026,7,20))*EXACT(Data!$C$2:$C$909,$A7)*Data!$D$2:$D$909) -> 11999 | C7: =SUMPRODUCT((Data!$A$2:$A$909=DATE(2026,7,21))*EXACT(Data!$C$2:$C$909,$A7)*Data!$D$2:$D$909) -> 11104 | D7: =SUMPRODUCT((Data!$A$2:$A$909=DATE(2026,7,22))*EXACT(Data!$C$2:$C$909,$A7)*Data!$D$2:$D$909) -> 10374 | E7: =SUMPRODUCT((Data!$A$2:$A$909=DATE(2026,7,23))*EXACT(Data!$C$2:$C$909,$A7)*Data!$D$2:$D$909) -> 10537 | F7: =SUMPRODUCT((Data!$A$2:$A$909=DATE(2026,7,24))*EXACT(Data!$C$2:$C$909,$A7)*Data!$D$2:$D$909) -> 10086 | G7: =SUMPRODUCT((Data!$A$2:$A$909=DATE(2026,7,25))*EXACT(Data!$C$2:$C$909,$A7)*Data!$D$2:$D$909) -> 6218 | H7: =SUMPRODUCT((Data!$A$2:$A$909=DATE(2026,7,26))*EXACT(Data!$C$2:$C$909,$A7)*Data!$D$2:$D$909) -> 6252 | I7: =SUM(B7:H7) -> 66570 | J7: =IF(B7=0,"",(H7-B7)/B7) -> -0.47895658
A8: GetCRSPersonInfo | B8: =SUMPRODUCT((Data!$A$2:$A$909=DATE(2026,7,20))*EXACT(Data!$C$2:$C$909,$A8)*Data!$D$2:$D$909) -> 34411 | C8: =SUMPRODUCT((Data!$A$2:$A$909=DATE(2026,7,21))*EXACT(Data!$C$2:$C$909,$A8)*Data!$D$2:$D$909) -> 32238 | D8: =SUMPRODUCT((Data!$A$2:$A$909=DATE(2026,7,22))*EXACT(Data!$C$2:$C$909,$A8)*Data!$D$2:$D$909) -> 31038 | E8: =SUMPRODUCT((Data!$A$2:$A$909=DATE(2026,7,23))*EXACT(Data!$C$2:$C$909,$A8)*Data!$D$2:$D$909) -> 33599 | F8: =SUMPRODUCT((Data!$A$2:$A$909=DATE(2026,7,24))*EXACT(Data!$C$2:$C$909,$A8)*Data!$D$2:$D$909) -> 34233 | G8: =SUMPRODUCT((Data!$A$2:$A$909=DATE(2026,7,25))*EXACT(Data!$C$2:$C$909,$A8)*Data!$D$2:$D$909) -> 16263 | H8: =SUMPRODUCT((Data!$A$2:$A$909=DATE(2026,7,26))*EXACT(Data!$C$2:$C$909,$A8)*Data!$D$2:$D$909) -> 14780 | I8: =SUM(B8:H8) -> 196562 | J8: =IF(B8=0,"",(H8-B8)/B8) -> -0.57048618
A9: SearchAllListInfo | B9: =SUMPRODUCT((Data!$A$2:$A$909=DATE(2026,7,20))*EXACT(Data!$C$2:$C$909,$A9)*Data!$D$2:$D$909) -> 8944 | C9: =SUMPRODUCT((Data!$A$2:$A$909=DATE(2026,7,21))*EXACT(Data!$C$2:$C$909,$A9)*Data!$D$2:$D$909) -> 8831 | D9: =SUMPRODUCT((Data!$A$2:$A$909=DATE(2026,7,22))*EXACT(Data!$C$2:$C$909,$A9)*Data!$D$2:$D$909) -> 7913 | E9: =SUMPRODUCT((Data!$A$2:$A$909=DATE(2026,7,23))*EXACT(Data!$C$2:$C$909,$A9)*Data!$D$2:$D$909) -> 7937 | F9: =SUMPRODUCT((Data!$A$2:$A$909=DATE(2026,7,24))*EXACT(Data!$C$2:$C$909,$A9)*Data!$D$2:$D$909) -> 7925 | G9: =SUMPRODUCT((Data!$A$2:$A$909=DATE(2026,7,25))*EXACT(Data!$C$2:$C$909,$A9)*Data!$D$2:$D$909) -> 3971 | H9: =SUMPRODUCT((Data!$A$2:$A$909=DATE(2026,7,26))*EXACT(Data!$C$2:$C$909,$A9)*Data!$D$2:$D$909) -> 3840 | I9: =SUM(B9:H9) -> 49361 | J9: =IF(B9=0,"",(H9-B9)/B9) -> -0.5706619
A10: UpdateMaintainPartyExtension | B10: =SUMPRODUCT((Data!$A$2:$A$909=DATE(2026,7,20))*EXACT(Data!$C$2:$C$909,$A10)*Data!$D$2:$D$909) -> 28126 | C10: =SUMPRODUCT((Data!$A$2:$A$909=DATE(2026,7,21))*EXACT(Data!$C$2:$C$909,$A10)*Data!$D$2:$D$909) -> 26366 | D10: =SUMPRODUCT((Data!$A$2:$A$909=DATE(2026,7,22))*EXACT(Data!$C$2:$C$909,$A10)*Data!$D$2:$D$909) -> 25082 | E10: =SUMPRODUCT((Data!$A$2:$A$909=DATE(2026,7,23))*EXACT(Data!$C$2:$C$909,$A10)*Data!$D$2:$D$909) -> 27255 | F10: =SUMPRODUCT((Data!$A$2:$A$909=DATE(2026,7,24))*EXACT(Data!$C$2:$C$909,$A10)*Data!$D$2:$D$909) -> 28163 | G10: =SUMPRODUCT((Data!$A$2:$A$909=DATE(2026,7,25))*EXACT(Data!$C$2:$C$909,$A10)*Data!$D$2:$D$909) -> 11528 | H10: =SUMPRODUCT((Data!$A$2:$A$909=DATE(2026,7,26))*EXACT(Data!$C$2:$C$909,$A10)*Data!$D$2:$D$909) -> 10545 | I10: =SUM(B10:H10) -> 157065 | J10: =IF(B10=0,"",(H10-B10)/B10) -> -0.62508
A11: MaintainPartyExtension | B11: =SUMPRODUCT((Data!$A$2:$A$909=DATE(2026,7,20))*EXACT(Data!$C$2:$C$909,$A11)*Data!$D$2:$D$909) -> 33229 | C11: =SUMPRODUCT((Data!$A$2:$A$909=DATE(2026,7,21))*EXACT(Data!$C$2:$C$909,$A11)*Data!$D$2:$D$909) -> 30970 | D11: =SUMPRODUCT((Data!$A$2:$A$909=DATE(2026,7,22))*EXACT(Data!$C$2:$C$909,$A11)*Data!$D$2:$D$909) -> 28959 | E11: =SUMPRODUCT((Data!$A$2:$A$909=DATE(2026,7,23))*EXACT(Data!$C$2:$C$909,$A11)*Data!$D$2:$D$909) -> 30930 | F11: =SUMPRODUCT((Data!$A$2:$A$909=DATE(2026,7,24))*EXACT(Data!$C$2:$C$909,$A11)*Data!$D$2:$D$909) -> 31677 | G11: =SUMPRODUCT((Data!$A$2:$A$909=DATE(2026,7,25))*EXACT(Data!$C$2:$C$909,$A11)*Data!$D$2:$D$909) -> 13717 | H11: =SUMPRODUCT((Data!$A$2:$A$909=DATE(2026,7,26))*EXACT(Data!$C$2:$C$909,$A11)*Data!$D$2:$D$909) -> 12445 | I11: =SUM(B11:H11) -> 181927 | J11: =IF(B11=0,"",(H11-B11)/B11) -> -0.62547775
A12: AddMaintainPartyExtension | B12: =SUMPRODUCT((Data!$A$2:$A$909=DATE(2026,7,20))*EXACT(Data!$C$2:$C$909,$A12)*Data!$D$2:$D$909) -> 5113 | C12: =SUMPRODUCT((Data!$A$2:$A$909=DATE(2026,7,21))*EXACT(Data!$C$2:$C$909,$A12)*Data!$D$2:$D$909) -> 4612 | D12: =SUMPRODUCT((Data!$A$2:$A$909=DATE(2026,7,22))*EXACT(Data!$C$2:$C$909,$A12)*Data!$D$2:$D$909) -> 3880 | E12: =SUMPRODUCT((Data!$A$2:$A$909=DATE(2026,7,23))*EXACT(Data!$C$2:$C$909,$A12)*Data!$D$2:$D$909) -> 3678 | F12: =SUMPRODUCT((Data!$A$2:$A$909=DATE(2026,7,24))*EXACT(Data!$C$2:$C$909,$A12)*Data!$D$2:$D$909) -> 3527 | G12: =SUMPRODUCT((Data!$A$2:$A$909=DATE(2026,7,25))*EXACT(Data!$C$2:$C$909,$A12)*Data!$D$2:$D$909) -> 2196 | H12: =SUMPRODUCT((Data!$A$2:$A$909=DATE(2026,7,26))*EXACT(Data!$C$2:$C$909,$A12)*Data!$D$2:$D$909) -> 1901 | I12: =SUM(B12:H12) -> 24907 | J12: =IF(B12=0,"",(H12-B12)/B12) -> -0.62820262
A13: AuthService | B13: =SUMPRODUCT((Data!$A$2:$A$909=DATE(2026,7,20))*EXACT(Data!$C$2:$C$909,$A13)*Data!$D$2:$D$909) -> 24399 | C13: =SUMPRODUCT((Data!$A$2:$A$909=DATE(2026,7,21))*EXACT(Data!$C$2:$C$909,$A13)*Data!$D$2:$D$909) -> 22101 | D13: =SUMPRODUCT((Data!$A$2:$A$909=DATE(2026,7,22))*EXACT(Data!$C$2:$C$909,$A13)*Data!$D$2:$D$909) -> 20748 | E13: =SUMPRODUCT((Data!$A$2:$A$909=DATE(2026,7,23))*EXACT(Data!$C$2:$C$909,$A13)*Data!$D$2:$D$909) -> 23169 | F13: =SUMPRODUCT((Data!$A$2:$A$909=DATE(2026,7,24))*EXACT(Data!$C$2:$C$909,$A13)*Data!$D$2:$D$909) -> 24312 | G13: =SUMPRODUCT((Data!$A$2:$A$909=DATE(2026,7,25))*EXACT(Data!$C$2:$C$909,$A13)*Data!$D$2:$D$909) -> 8704 | H13: =SUMPRODUCT((Data!$A$2:$A$909=DATE(2026,7,26))*EXACT(Data!$C$2:$C$909,$A13)*Data!$D$2:$D$909) -> 7753 | I13: =SUM(B13:H13) -> 131186 | J13: =IF(B13=0,"",(H13-B13)/B13) -> -0.68224108
... A43: searchParty | B43: =SUMPRODUCT((Data!$A$2:$A$909=DATE(2026,7,20))*EXACT(Data!$C$2:$C$909,$A43)*Data!$D$2:$D$909) -> 0 | C43: =SUMPRODUCT((Data!$A$2:$A$909=DATE(2026,7,21))*EXACT(Data!$C$2:$C$909,$A43)*Data!$D$2:$D$909) -> 1 | D43: =SUMPRODUCT((Data!$A$2:$A$909=DATE(2026,7,22))*EXACT(Data!$C$2:$C$909,$A43)*Data!$D$2:$D$909) -> 0 | E43: =SUMPRODUCT((Data!$A$2:$A$909=DATE(2026,7,23))*EXACT(Data!$C$2:$C$909,$A43)*Data!$D$2:$D$909) -> 0 | F43: =SUMPRODUCT((Data!$A$2:$A$909=DATE(2026,7,24))*EXACT(Data!$C$2:$C$909,$A43)*Data!$D$2:$D$909) -> 0 | G43: =SUMPRODUCT((Data!$A$2:$A$909=DATE(2026,7,25))*EXACT(Data!$C$2:$C$909,$A43)*Data!$D$2:$D$909) -> 0 | H43: =SUMPRODUCT((Data!$A$2:$A$909=DATE(2026,7,26))*EXACT(Data!$C$2:$C$909,$A43)*Data!$D$2:$D$909) -> 0 | I43: =SUM(B43:H43) -> 1 | J43: =IF(B43=0,"",(H43-B43)/B43)
A45: Growth % = (26-Jul count - 20-Jul count) / 20-Jul count. Blank = no activity on 20-Jul (growth undefined). Note: 20-Jul is a Monday and 26-Jul a Sunday, so weekday/weekend traffic patterns affect the rate. Service names are matched case-sensitively (kycScoreEngineForOrg and KYCScoreEngineForOrg are distinct). Source: query_log_channel_union_all_1.xlsx (sheet CustomQuery), uploaded by user.

Sheet Channel-Service Growth
A1: Channel | B1: Service | C1: 20-Jul | D1: 21-Jul | E1: 22-Jul | F1: 23-Jul | G1: 24-Jul | H1: 25-Jul | I1: 26-Jul | J1: Total | K1: Growth %
A2: AML | B2: FuzzySearchAllListInfoPlusMA | C2: =SUMPRODUCT((Data!$A$2:$A$909=DATE(2026,7,20))*EXACT(Data!$B$2:$B$909,$A2)*EXACT(Data!$C$2:$C$909,$B2)*Data!$D$2:$D$909) -> 64 | D2: =SUMPRODUCT((Data!$A$2:$A$909=DATE(2026,7,21))*EXACT(Data!$B$2:$B$909,$A2)*EXACT(Data!$C$2:$C$909,$B2)*Data!$D$2:$D$909) -> 7 | E2: =SUMPRODUCT((Data!$A$2:$A$909=DATE(2026,7,22))*EXACT(Data!$B$2:$B$909,$A2)*EXACT(Data!$C$2:$C$909,$B2)*Data!$D$2:$D$909) -> 10 | F2: =SUMPRODUCT((Data!$A$2:$A$909=DATE(2026,7,23))*EXACT(Data!$B$2:$B$909,$A2)*EXACT(Data!$C$2:$C$909,$B2)*Data!$D$2:$D$909) -> 5 | G2: =SUMPRODUCT((Data!$A$2:$A$909=DATE(2026,7,24))*EXACT(Data!$B$2:$B$909,$A2)*EXACT(Data!$C$2:$C$909,$B2)*Data!$D$2:$D$909) -> 20 | H2: =SUMPRODUCT((Data!$A$2:$A$909=DATE(2026,7,25))*EXACT(Data!$B$2:$B$909,$A2)*EXACT(Data!$C$2:$C$909,$B2)*Data!$D$2:$D$909) -> 0 | I2: =SUMPRODUCT((Data!$A$2:$A$909=DATE(2026,7,26))*EXACT(Data!$B$2:$B$909,$A2)*EXACT(Data!$C$2:$C$909,$B2)*Data!$D$2:$D$909) -> 0 | J2: =SUM(C2:I2) -> 106 | K2: =IF(C2=0,"",(I2-C2)/C2) -> -1
A3: AML | B3: GetAllCodeTablePlusMA | C3: =SUMPRODUCT((Data!$A$2:$A$909=DATE(2026,7,20))*EXACT(Data!$B$2:$B$909,$A3)*EXACT(Data!$C$2:$C$909,$B3)*Data!$D$2:$D$909) -> 15 | D3: =SUMPRODUCT((Data!$A$2:$A$909=DATE(2026,7,21))*EXACT(Data!$B$2:$B$909,$A3)*EXACT(Data!$C$2:$C$909,$B3)*Data!$D$2:$D$909) -> 3 | E3: =SUMPRODUCT((Data!$A$2:$A$909=DATE(2026,7,22))*EXACT(Data!$B$2:$B$909,$A3)*EXACT(Data!$C$2:$C$909,$B3)*Data!$D$2:$D$909) -> 11 | F3: =SUMPRODUCT((Data!$A$2:$A$909=DATE(2026,7,23))*EXACT(Data!$B$2:$B$909,$A3)*EXACT(Data!$C$2:$C$909,$B3)*Data!$D$2:$D$909) -> 13 | G3: =SUMPRODUCT((Data!$A$2:$A$909=DATE(2026,7,24))*EXACT(Data!$B$2:$B$909,$A3)*EXACT(Data!$C$2:$C$909,$B3)*Data!$D$2:$D$909) -> 7 | H3: =SUMPRODUCT((Data!$A$2:$A$909=DATE(2026,7,25))*EXACT(Data!$B$2:$B$909,$A3)*EXACT(Data!$C$2:$C$909,$B3)*Data!$D$2:$D$909) -> 0 | I3: =SUMPRODUCT((Data!$A$2:$A$909=DATE(2026,7,26))*EXACT(Data!$B$2:$B$909,$A3)*EXACT(Data!$C$2:$C$909,$B3)*Data!$D$2:$D$909) -> 0 | J3: =SUM(C3:I3) -> 49 | K3: =IF(C3=0,"",(I3-C3)/C3) -> -1
A4: AML | B4: GetListSubTypePlusMA | C4: =SUMPRODUCT((Data!$A$2:$A$909=DATE(2026,7,20))*EXACT(Data!$B$2:$B$909,$A4)*EXACT(Data!$C$2:$C$909,$B4)*Data!$D$2:$D$909) -> 12 | D4: =SUMPRODUCT((Data!$A$2:$A$909=DATE(2026,7,21))*EXACT(Data!$B$2:$B$909,$A4)*EXACT(Data!$C$2:$C$909,$B4)*Data!$D$2:$D$909) -> 1 | E4: =SUMPRODUCT((Data!$A$2:$A$909=DATE(2026,7,22))*EXACT(Data!$B$2:$B$909,$A4)*EXACT(Data!$C$2:$C$909,$B4)*Data!$D$2:$D$909) -> 8 | F4: =SUMPRODUCT((Data!$A$2:$A$909=DATE(2026,7,23))*EXACT(Data!$B$2:$B$909,$A4)*EXACT(Data!$C$2:$C$909,$B4)*Data!$D$2:$D$909) -> 1 | G4: =SUMPRODUCT((Data!$A$2:$A$909=DATE(2026,7,24))*EXACT(Data!$B$2:$B$909,$A4)*EXACT(Data!$C$2:$C$909,$B4)*Data!$D$2:$D$909) -> 0 | H4: =SUMPRODUCT((Data!$A$2:$A$909=DATE(2026,7,25))*EXACT(Data!$B$2:$B$909,$A4)*EXACT(Data!$C$2:$C$909,$B4)*Data!$D$2:$D$909) -> 0 | I4: =SUMPRODUCT((Data!$A$2:$A$909=DATE(2026,7,26))*EXACT(Data!$B$2:$B$909,$A4)*EXACT(Data!$C$2:$C$909,$B4)*Data!$D$2:$D$909) -> 0 | J4: =SUM(C4:I4) -> 22 | K4: =IF(C4=0,"",(I4-C4)/C4) -> -1
A5: AML | B5: SearchAllListInfoPlusMA | C5: =SUMPRODUCT((Data!$A$2:$A$909=DATE(2026,7,20))*EXACT(Data!$B$2:$B$909,$A5)*EXACT(Data!$C$2:$C$909,$B5)*Data!$D$2:$D$909) -> 511 | D5: =SUMPRODUCT((Data!$A$2:$A$909=DATE(2026,7,21))*EXACT(Data!$B$2:$B$909,$A5)*EXACT(Data!$C$2:$C$909,$B5)*Data!$D$2:$D$909) -> 460 | E5: =SUMPRODUCT((Data!$A$2:$A$909=DATE(2026,7,22))*EXACT(Data!$B$2:$B$909,$A5)*EXACT(Data!$C$2:$C$909,$B5)*Data!$D$2:$D$909) -> 455 | F5: =SUMPRODUCT((Data!$A$2:$A$909=DATE(2026,7,23))*EXACT(Data!$B$2:$B$909,$A5)*EXACT(Data!$C$2:$C$909,$B5)*Data!$D$2:$D$909) -> 427 | G5: =SUMPRODUCT((Data!$A$2:$A$909=DATE(2026,7,24))*EXACT(Data!$B$2:$B$909,$A5)*EXACT(Data!$C$2:$C$909,$B5)*Data!$D$2:$D$909) -> 617 | H5: =SUMPRODUCT((Data!$A$2:$A$909=DATE(2026,7,25))*EXACT(Data!$B$2:$B$909,$A5)*EXACT(Data!$C$2:$C$909,$B5)*Data!$D$2:$D$909) -> 65 | I5: =SUMPRODUCT((Data!$A$2:$A$909=DATE(2026,7,26))*EXACT(Data!$B$2:$B$909,$A5)*EXACT(Data!$C$2:$C$909,$B5)*Data!$D$2:$D$909) -> 102 | J5: =SUM(C5:I5) -> 2637 | K5: =IF(C5=0,"",(I5-C5)/C5) -> -0.80039139
A6: AML | B6: UploadNetbay | C6: =SUMPRODUCT((Data!$A$2:$A$909=DATE(2026,7,20))*EXACT(Data!$B$2:$B$909,$A6)*EXACT(Data!$C$2:$C$909,$B6)*Data!$D$2:$D$909) -> 1 | D6: =SUMPRODUCT((Data!$A$2:$A$909=DATE(2026,7,21))*EXACT(Data!$B$2:$B$909,$A6)*EXACT(Data!$C$2:$C$909,$B6)*Data!$D$2:$D$909) -> 0 | E6: =SUMPRODUCT((Data!$A$2:$A$909=DATE(2026,7,22))*EXACT(Data!$B$2:$B$909,$A6)*EXACT(Data!$C$2:$C$909,$B6)*Data!$D$2:$D$909) -> 0 | F6: =SUMPRODUCT((Data!$A$2:$A$909=DATE(2026,7,23))*EXACT(Data!$B$2:$B$909,$A6)*EXACT(Data!$C$2:$C$909,$B6)*Data!$D$2:$D$909) -> 0 | G6: =SUMPRODUCT((Data!$A$2:$A$909=DATE(2026,7,24))*EXACT(Data!$B$2:$B$909,$A6)*EXACT(Data!$C$2:$C$909,$B6)*Data!$D$2:$D$909) -> 0 | H6: =SUMPRODUCT((Data!$A$2:$A$909=DATE(2026,7,25))*EXACT(Data!$B$2:$B$909,$A6)*EXACT(Data!$C$2:$C$909,$B6)*Data!$D$2:$D$909) -> 0 | I6: =SUMPRODUCT((Data!$A$2:$A$909=DATE(2026,7,26))*EXACT(Data!$B$2:$B$909,$A6)*EXACT(Data!$C$2:$C$909,$B6)*Data!$D$2:$D$909) -> 0 | J6: =SUM(C6:I6) -> 1 | K6: =IF(C6=0,"",(I6-C6)/C6) -> -1
A7: AMSC | B7: kycScoreEngineForOrg | C7: =SUMPRODUCT((Data!$A$2:$A$909=DATE(2026,7,20))*EXACT(Data!$B$2:$B$909,$A7)*EXACT(Data!$C$2:$C$909,$B7)*Data!$D$2:$D$909) -> 0 | D7: =SUMPRODUCT((Data!$A$2:$A$909=DATE(2026,7,21))*EXACT(Data!$B$2:$B$909,$A7)*EXACT(Data!$C$2:$C$909,$B7)*Data!$D$2:$D$909) -> 0 | E7: =SUMPRODUCT((Data!$A$2:$A$909=DATE(2026,7,22))*EXACT(Data!$B$2:$B$909,$A7)*EXACT(Data!$C$2:$C$909,$B7)*Data!$D$2:$D$909) -> 2 | F7: =SUMPRODUCT((Data!$A$2:$A$909=DATE(2026,7,23))*EXACT(Data!$B$2:$B$909,$A7)*EXACT(Data!$C$2:$C$909,$B7)*Data!$D$2:$D$909) -> 2 | G7: =SUMPRODUCT((Data!$A$2:$A$909=DATE(2026,7,24))*EXACT(Data!$B$2:$B$909,$A7)*EXACT(Data!$C$2:$C$909,$B7)*Data!$D$2:$D$909) -> 0 | H7: =SUMPRODUCT((Data!$A$2:$A$909=DATE(2026,7,25))*EXACT(Data!$B$2:$B$909,$A7)*EXACT(Data!$C$2:$C$909,$B7)*Data!$D$2:$D$909) -> 0 | I7: =SUMPRODUCT((Data!$A$2:$A$909=DATE(2026,7,26))*EXACT(Data!$B$2:$B$909,$A7)*EXACT(Data!$C$2:$C$909,$B7)*Data!$D$2:$D$909) -> 6 | J7: =SUM(C7:I7) -> 10 | K7: =IF(C7=0,"",(I7-C7)/C7)
A8: AMSC_POPAC | B8: AuthService | C8: =SUMPRODUCT((Data!$A$2:$A$909=DATE(2026,7,20))*EXACT(Data!$B$2:$B$909,$A8)*EXACT(Data!$C$2:$C$909,$B8)*Data!$D$2:$D$909) -> 0 | D8: =SUMPRODUCT((Data!$A$2:$A$909=DATE(2026,7,21))*EXACT(Data!$B$2:$B$909,$A8)*EXACT(Data!$C$2:$C$909,$B8)*Data!$D$2:$D$909) -> 0 | E8: =SUMPRODUCT((Data!$A$2:$A$909=DATE(2026,7,22))*EXACT(Data!$B$2:$B$909,$A8)*EXACT(Data!$C$2:$C$909,$B8)*Data!$D$2:$D$909) -> 3 | F8: =SUMPRODUCT((Data!$A$2:$A$909=DATE(2026,7,23))*EXACT(Data!$B$2:$B$909,$A8)*EXACT(Data!$C$2:$C$909,$B8)*Data!$D$2:$D$909) -> 2 | G8: =SUMPRODUCT((Data!$A$2:$A$909=DATE(2026,7,24))*EXACT(Data!$B$2:$B$909,$A8)*EXACT(Data!$C$2:$C$909,$B8)*Data!$D$2:$D$909) -> 0 | H8: =SUMPRODUCT((Data!$A$2:$A$909=DATE(2026,7,25))*EXACT(Data!$B$2:$B$909,$A8)*EXACT(Data!$C$2:$C$909,$B8)*Data!$D$2:$D$909) -> 0 | I8: =SUMPRODUCT((Data!$A$2:$A$909=DATE(2026,7,26))*EXACT(Data!$B$2:$B$909,$A8)*EXACT(Data!$C$2:$C$909,$B8)*Data!$D$2:$D$909) -> 6 | J8: =SUM(C8:I8) -> 11 | K8: =IF(C8=0,"",(I8-C8)/C8)
A9: AMSC_POPAC | B9: GetCRSOrgInfo | C9: =SUMPRODUCT((Data!$A$2:$A$909=DATE(2026,7,20))*EXACT(Data!$B$2:$B$909,$A9)*EXACT(Data!$C$2:$C$909,$B9)*Data!$D$2:$D$909) -> 0 | D9: =SUMPRODUCT((Data!$A$2:$A$909=DATE(2026,7,21))*EXACT(Data!$B$2:$B$909,$A9)*EXACT(Data!$C$2:$C$909,$B9)*Data!$D$2:$D$909) -> 0 | E9: =SUMPRODUCT((Data!$A$2:$A$909=DATE(2026,7,22))*EXACT(Data!$B$2:$B$909,$A9)*EXACT(Data!$C$2:$C$909,$B9)*Data!$D$2:$D$909) -> 1 | F9: =SUMPRODUCT((Data!$A$2:$A$909=DATE(2026,7,23))*EXACT(Data!$B$2:$B$909,$A9)*EXACT(Data!$C$2:$C$909,$B9)*Data!$D$2:$D$909) -> 1 | G9: =SUMPRODUCT((Data!$A$2:$A$909=DATE(2026,7,24))*EXACT(Data!$B$2:$B$909,$A9)*EXACT(Data!$C$2:$C$909,$B9)*Data!$D$2:$D$909) -> 0 | H9: =SUMPRODUCT((Data!$A$2:$A$909=DATE(2026,7,25))*EXACT(Data!$B$2:$B$909,$A9)*EXACT(Data!$C$2:$C$909,$B9)*Data!$D$2:$D$909) -> 0 | I9: =SUMPRODUCT((Data!$A$2:$A$909=DATE(2026,7,26))*EXACT(Data!$B$2:$B$909,$A9)*EXACT(Data!$C$2:$C$909,$B9)*Data!$D$2:$D$909) -> 2 | J9: =SUM(C9:I9) -> 4 | K9: =IF(C9=0,"",(I9-C9)/C9)
A10: AMSC_POPAC | B10: MaintainCRSOrgInfo | C10: =SUMPRODUCT((Data!$A$2:$A$909=DATE(2026,7,20))*EXACT(Data!$B$2:$B$909,$A10)*EXACT(Data!$C$2:$C$909,$B10)*Data!$D$2:$D$909) -> 0 | D10: =SUMPRODUCT((Data!$A$2:$A$909=DATE(2026,7,21))*EXACT(Data!$B$2:$B$909,$A10)*EXACT(Data!$C$2:$C$909,$B10)*Data!$D$2:$D$909) -> 0 | E10: =SUMPRODUCT((Data!$A$2:$A$909=DATE(2026,7,22))*EXACT(Data!$B$2:$B$909,$A10)*EXACT(Data!$C$2:$C$909,$B10)*Data!$D$2:$D$909) -> 1 | F10: =SUMPRODUCT((Data!$A$2:$A$909=DATE(2026,7,23))*EXACT(Data!$B$2:$B$909,$A10)*EXACT(Data!$C$2:$C$909,$B10)*Data!$D$2:$D$909) -> 1 | G10: =SUMPRODUCT((Data!$A$2:$A$909=DATE(2026,7,24))*EXACT(Data!$B$2:$B$909,$A10)*EXACT(Data!$C$2:$C$909,$B10)*Data!$D$2:$D$909) -> 0 | H10: =SUMPRODUCT((Data!$A$2:$A$909=DATE(2026,7,25))*EXACT(Data!$B$2:$B$909,$A10)*EXACT(Data!$C$2:$C$909,$B10)*Data!$D$2:$D$909) -> 0 | I10: =SUMPRODUCT((Data!$A$2:$A$909=DATE(2026,7,26))*EXACT(Data!$B$2:$B$909,$A10)*EXACT(Data!$C$2:$C$909,$B10)*Data!$D$2:$D$909) -> 1 | J10: =SUM(C10:I10) -> 3 | K10: =IF(C10=0,"",(I10-C10)/C10)
A11: AMSC_POPAC | B11: RegulatoryVerificationPlusMA | C11: =SUMPRODUCT((Data!$A$2:$A$909=DATE(2026,7,20))*EXACT(Data!$B$2:$B$909,$A11)*EXACT(Data!$C$2:$C$909,$B11)*Data!$D$2:$D$909) -> 7 | D11: =SUMPRODUCT((Data!$A$2:$A$909=DATE(2026,7,21))*EXACT(Data!$B$2:$B$909,$A11)*EXACT(Data!$C$2:$C$909,$B11)*Data!$D$2:$D$909) -> 5 | E11: =SUMPRODUCT((Data!$A$2:$A$909=DATE(2026,7,22))*EXACT(Data!$B$2:$B$909,$A11)*EXACT(Data!$C$2:$C$909,$B11)*Data!$D$2:$D$909) -> 11 | F11: =SUMPRODUCT((Data!$A$2:$A$909=DATE(2026,7,23))*EXACT(Data!$B$2:$B$909,$A11)*EXACT(Data!$C$2:$C$909,$B11)*Data!$D$2:$D$909) -> 2 | G11: =SUMPRODUCT((Data!$A$2:$A$909=DATE(2026,7,24))*EXACT(Data!$B$2:$B$909,$A11)*EXACT(Data!$C$2:$C$909,$B11)*Data!$D$2:$D$909) -> 6 | H11: =SUMPRODUCT((Data!$A$2:$A$909=DATE(2026,7,25))*EXACT(Data!$B$2:$B$909,$A11)*EXACT(Data!$C$2:$C$909,$B11)*Data!$D$2:$D$909) -> 3 | I11: =SUMPRODUCT((Data!$A$2:$A$909=DATE(2026,7,26))*EXACT(Data!$B$2:$B$909,$A11)*EXACT(Data!$C$2:$C$909,$B11)*Data!$D$2:$D$909) -> 5 | J11: =SUM(C11:I11) -> 39 | K11: =IF(C11=0,"",(I11-C11)/C11) -> -0.28571429
A12: BASE24WS_CHKAML | B12: AuthService | C12: =SUMPRODUCT((Data!$A$2:$A$909=DATE(2026,7,20))*EXACT(Data!$B$2:$B$909,$A12)*EXACT(Data!$C$2:$C$909,$B12)*Data!$D$2:$D$909) -> 4 | D12: =SUMPRODUCT((Data!$A$2:$A$909=DATE(2026,7,21))*EXACT(Data!$B$2:$B$909,$A12)*EXACT(Data!$C$2:$C$909,$B12)*Data!$D$2:$D$909) -> 4 | E12: =SUMPRODUCT((Data!$A$2:$A$909=DATE(2026,7,22))*EXACT(Data!$B$2:$B$909,$A12)*EXACT(Data!$C$2:$C$909,$B12)*Data!$D$2:$D$909) -> 4 | F12: =SUMPRODUCT((Data!$A$2:$A$909=DATE(2026,7,23))*EXACT(Data!$B$2:$B$909,$A12)*EXACT(Data!$C$2:$C$909,$B12)*Data!$D$2:$D$909) -> 4 | G12: =SUMPRODUCT((Data!$A$2:$A$909=DATE(2026,7,24))*EXACT(Data!$B$2:$B$909,$A12)*EXACT(Data!$C$2:$C$909,$B12)*Data!$D$2:$D$909) -> 4 | H12: =SUMPRODUCT((Data!$A$2:$A$909=DATE(2026,7,25))*EXACT(Data!$B$2:$B$909,$A12)*EXACT(Data!$C$2:$C$909,$B12)*Data!$D$2:$D$909) -> 4 | I12: =SUMPRODUCT((Data!$A$2:$A$909=DATE(2026,7,26))*EXACT(Data!$B$2:$B$909,$A12)*EXACT(Data!$C$2:$C$909,$B12)*Data!$D$2:$D$909) -> 4 | J12: =SUM(C12:I12) -> 28 | K12: =IF(C12=0,"",(I12-C12)/C12) -> 0
A13: BASE24WS_CHKAML | B13: SearchAMLListInfoByCid | C13: =SUMPRODUCT((Data!$A$2:$A$909=DATE(2026,7,20))*EXACT(Data!$B$2:$B$909,$A13)*EXACT(Data!$C$2:$C$909,$B13)*Data!$D$2:$D$909) -> 130238 | D13: =SUMPRODUCT((Data!$A$2:$A$909=DATE(2026,7,21))*EXACT(Data!$B$2:$B$909,$A13)*EXACT(Data!$C$2:$C$909,$B13)*Data!$D$2:$D$909) -> 118085 | E13: =SUMPRODUCT((Data!$A$2:$A$909=DATE(2026,7,22))*EXACT(Data!$B$2:$B$909,$A13)*EXACT(Data!$C$2:$C$909,$B13)*Data!$D$2:$D$909) -> 112992 | F13: =SUMPRODUCT((Data!$A$2:$A$909=DATE(2026,7,23))*EXACT(Data!$B$2:$B$909,$A13)*EXACT(Data!$C$2:$C$909,$B13)*Data!$D$2:$D$909) -> 108922 | G13: =SUMPRODUCT((Data!$A$2:$A$909=DATE(2026,7,24))*EXACT(Data!$B$2:$B$909,$A13)*EXACT(Data!$C$2:$C$909,$B13)*Data!$D$2:$D$909) -> 115880 | H13: =SUMPRODUCT((Data!$A$2:$A$909=DATE(2026,7,25))*EXACT(Data!$B$2:$B$909,$A13)*EXACT(Data!$C$2:$C$909,$B13)*Data!$D$2:$D$909) -> 111368 | I13: =SUMPRODUCT((Data!$A$2:$A$909=DATE(2026,7,26))*EXACT(Data!$B$2:$B$909,$A13)*EXACT(Data!$C$2:$C$909,$B13)*Data!$D$2:$D$909) -> 103866 | J13: =SUM(C13:I13) -> 801351 | K13: =IF(C13=0,"",(I13-C13)/C13) -> -0.20249082
... A160: eKYC_SP-FIXED-IAL | B160: RegulatoryVerification | C160: =SUMPRODUCT((Data!$A$2:$A$909=DATE(2026,7,20))*EXACT(Data!$B$2:$B$909,$A160)*EXACT(Data!$C$2:$C$909,$B160)*Data!$D$2:$D$909) -> 5836 | D160: =SUMPRODUCT((Data!$A$2:$A$909=DATE(2026,7,21))*EXACT(Data!$B$2:$B$909,$A160)*EXACT(Data!$C$2:$C$909,$B160)*Data!$D$2:$D$909) -> 6257 | E160: =SUMPRODUCT((Data!$A$2:$A$909=DATE(2026,7,22))*EXACT(Data!$B$2:$B$909,$A160)*EXACT(Data!$C$2:$C$909,$B160)*Data!$D$2:$D$909) -> 4381 | F160: =SUMPRODUCT((Data!$A$2:$A$909=DATE(2026,7,23))*EXACT(Data!$B$2:$B$909,$A160)*EXACT(Data!$C$2:$C$909,$B160)*Data!$D$2:$D$909) -> 4564 | G160: =SUMPRODUCT((Data!$A$2:$A$909=DATE(2026,7,24))*EXACT(Data!$B$2:$B$909,$A160)*EXACT(Data!$C$2:$C$909,$B160)*Data!$D$2:$D$909) -> 3350 | H160: =SUMPRODUCT((Data!$A$2:$A$909=DATE(2026,7,25))*EXACT(Data!$B$2:$B$909,$A160)*EXACT(Data!$C$2:$C$909,$B160)*Data!$D$2:$D$909) -> 2028 | I160: =SUMPRODUCT((Data!$A$2:$A$909=DATE(2026,7,26))*EXACT(Data!$B$2:$B$909,$A160)*EXACT(Data!$C$2:$C$909,$B160)*Data!$D$2:$D$909) -> 1932 | J160: =SUM(C160:I160) -> 28348 | K160: =IF(C160=0,"",(I160-C160)/C160) -> -0.66895134
A162: Growth % = (26-Jul count - 20-Jul count) / 20-Jul count. Blank = no activity on 20-Jul (growth undefined). Note: 20-Jul is a Monday and 26-Jul a Sunday, so weekday/weekend traffic patterns affect the rate. Service names are matched case-sensitively (kycScoreEngineForOrg and KYCScoreEngineForOrg are distinct). Source: query_log_channel_union_all_1.xlsx (sheet CustomQuery), uploaded by user.
